Workbook

Sheet Controls Tracker
A1: ISMS Control Tracker · ISO 27001:2022 Annex A · NIS2 Art. 21 | O1: Legende Status
A2: Nr. | B2: Control ID | C2: Control Name (Deutsch) | D2: Kategorie | E2: NIS2 Artikel | F2: Status | G2: Zweck / Ziel | H2: Umsetzungsmaßnahmen | I2: Verantwortlicher | J2: Datum Umsetzung | K2: Nachweise / Referenz | L2: Kommentar | O2: Status | P2: Bedeutung
A3: 1 | B3: 5.1 | C3: Richtlinien zur Informationssicherheit | D3: Organisatorisch | E3: Art.21(2)(a) | F3: Nicht umgesetzt | O3: Umgesetzt | P3: Vollständig implementiert
A4: 2 | B4: 5.2 | C4: Rollen und Verantwortlichkeiten | D4: Organisatorisch | E4: Art.21(2)(a) | F4: Nicht umgesetzt | O4: Teilweise | P4: In Umsetzung / unvollständig
A5: 3 | B5: 5.3 | C5: Aufgabentrennung | D5: Organisatorisch | E5: Art.21(2)(a) | F5: Nicht umgesetzt | O5: Nicht umgesetzt | P5: Noch nicht begonnen
A6: 4 | B6: 5.4 | C6: Managementverantwortlichkeiten | D6: Organisatorisch | E6: – | F6: Nicht umgesetzt
A7: 5 | B7: 5.5 | C7: Kontakt mit Behörden | D7: Organisatorisch | E7: – | F7: Nicht umgesetzt
A8: 6 | B8: 5.6 | C8: Kontakt mit Interessengruppen | D8: Organisatorisch | E8: – | F8: Nicht umgesetzt
A9: 7 | B9: 5.7 | C9: Threat Intelligence | D9: Organisatorisch | E9: – | F9: Nicht umgesetzt
A10: 8 | B10: 5.8 | C10: Informationssicherheit im Projektmanagement | D10: Organisatorisch | E10: – | F10: Nicht umgesetzt
A11: 9 | B11: 5.9 | C11: Inventar der Informationen und Assets | D11: Organisatorisch | E11: Art.21(2)(i) | F11: Nicht umgesetzt
A12: 10 | B12: 5.10 | C12: Akzeptable Nutzung von Informationen und Assets | D12: Organisatorisch | E12: Art.21(2)(i) | F12: Nicht umgesetzt
A13: 11 | B13: 5.11 | C13: Rückgabe von Assets | D13: Organisatorisch | E13: Art.21(2)(i) | F13: Nicht umgesetzt
A14: 12 | B14: 5.12 | C14: Klassifizierung von Informationen | D14: Organisatorisch | E14: – | F14: Nicht umgesetzt
A15: 13 | B15: 5.13 | C15: Kennzeichnung von Informationen | D15: Organisatorisch | E15: – | F15: Nicht umgesetzt
A16: 14 | B16: 5.14 | C16: Informationsübertragung | D16: Organisatorisch | E16: Art.21(2)(j) | F16: Nicht umgesetzt
A17: 15 | B17: 5.15 | C17: Zugriffskontrolle | D17: Organisatorisch | E17: Art.21(2)(i) | F17: Nicht umgesetzt
... A95: 93 | B95: 8.34 | C95: Schutz von Informationssystemen bei Audittests | D95: Technisch | E95: – | F95: Nicht umgesetzt

Sheet Statistik
B1: ISMS Umsetzungsstatistik
B3: Status | C3: Anzahl | D3: Anteil | E3: Fortschritt
B4: ✓ Umgesetzt | C4: =COUNTIF('Controls Tracker'!$F$3:$F$95,"Umgesetzt") | D4: =C4/93 | E4: =REPT("█",ROUND(C4/93*20,0))&REPT("░",20-ROUND(C4/93*20,0))
B5: ◑ Teilweise | C5: =COUNTIF('Controls Tracker'!$F$3:$F$95,"Teilweise") | D5: =C5/93 | E5: =REPT("█",ROUND(C5/93*20,0))&REPT("░",20-ROUND(C5/93*20,0))
B6: ✗ Nicht umgesetzt | C6: =COUNTIF('Controls Tracker'!$F$3:$F$95,"Nicht umgesetzt") | D6: =C6/93 | E6: =REPT("█",ROUND(C6/93*20,0))&REPT("░",20-ROUND(C6/93*20,0))
B7: Gesamt | C7: 93 | D7: =C4+C5+C6
B9: NIS2 Art. 21 — Erfüllungsgrad
B10: Artikel | C10: Bezeichnung | D10: Umgesetzt | E10: Gesamt | F10: Anteil
B11: Art. 21(2)(a) | C11: Risikoanalyse | D11: =COUNTIFS('Controls Tracker'!$B$3:$B$95,"5.1",'Controls Tracker'!$F$3:$F$95,"Umgesetzt")+COUNTIFS('Controls Tracker'!$B$3:$B$95,"5.2",'Controls Tracker'!$F$3:$F$95,"Umgesetzt")+COUNTIFS('Controls Tracker'!$B$3:$B$95,"5.3",'Controls Tracker'!$F$3:$F$95,"Umgesetzt")+COUNTIFS('Controls Tracker'!$B$3:$B$95,"6.1",'Controls Tracker'!$F$3:$F$95,"Umgesetzt")+COUNTIFS('Controls Tracker'!$B$3:$B$95,"8.2",'Controls Tracker'!$F$3:$F$95,"Umgesetzt")+COUNTIFS('Controls Tracker'!$B$3:$B$95,"8.3",'Controls Tracker'!$F$3:$F$95,"Umgesetzt") | E11: 6 | F11: =D11/E11
B12: Art. 21(2)(b) | C12: Incident Handling | D12: =COUNTIFS('Controls Tracker'!$B$3:$B$95,"5.24",'Controls Tracker'!$F$3:$F$95,"Umgesetzt")+COUNTIFS('Controls Tracker'!$B$3:$B$95,"5.25",'Controls Tracker'!$F$3:$F$95,"Umgesetzt")+COUNTIFS('Controls Tracker'!$B$3:$B$95,"5.26",'Controls Tracker'!$F$3:$F$95,"Umgesetzt")+COUNTIFS('Controls Tracker'!$B$3:$B$95,"5.27",'Controls Tracker'!$F$3:$F$95,"Umgesetzt")+COUNTIFS('Controls Tracker'!$B$3:$B$95,"5.28",'Controls Tracker'!$F$3:$F$95,"Umgesetzt") | E12: 5 | F12: =D12/E12
B13: Art. 21(2)(c) | C13: BCM & Disaster Recovery | D13: =COUNTIFS('Controls Tracker'!$B$3:$B$95,"5.29",'Controls Tracker'!$F$3:$F$95,"Umgesetzt")+COUNTIFS('Controls Tracker'!$B$3:$B$95,"5.30",'Controls Tracker'!$F$3:$F$95,"Umgesetzt")+COUNTIFS('Controls Tracker'!$B$3:$B$95,"8.13",'Controls Tracker'!$F$3:$F$95,"Umgesetzt")+COUNTIFS('Controls Tracker'!$B$3:$B$95,"8.14",'Controls Tracker'!$F$3:$F$95,"Umgesetzt") | E13: 4 | F13: =D13/E13
B14: Art. 21(2)(d) | C14: Lieferkettensicherheit | D14: =COUNTIFS('Controls Tracker'!$B$3:$B$95,"5.19",'Controls Tracker'!$F$3:$F$95,"Umgesetzt")+COUNTIFS('Controls Tracker'!$B$3:$B$95,"5.20",'Controls Tracker'!$F$3:$F$95,"Umgesetzt")+COUNTIFS('Controls Tracker'!$B$3:$B$95,"5.21",'Controls Tracker'!$F$3:$F$95,"Umgesetzt")+COUNTIFS('Controls Tracker'!$B$3:$B$95,"5.22",'Controls Tracker'!$F$3:$F$95,"Umgesetzt")+COUNTIFS('Controls Tracker'!$B$3:$B$95,"5.23",'Controls Tracker'!$F$3:$F$95,"Umgesetzt") | E14: 5 | F14: =D14/E14
B15: Art. 21(2)(e) | C15: Sichere Entwicklung | D15: =COUNTIFS('Controls Tracker'!$B$3:$B$95,"8.25",'Controls Tracker'!$F$3:$F$95,"Umgesetzt")+COUNTIFS('Controls Tracker'!$B$3:$B$95,"8.26",'Controls Tracker'!$F$3:$F$95,"Umgesetzt")+COUNTIFS('Controls Tracker'!$B$3:$B$95,"8.27",'Controls Tracker'!$F$3:$F$95,"Umgesetzt")+COUNTIFS('Controls Tracker'!$B$3:$B$95,"8.28",'Controls Tracker'!$F$3:$F$95,"Umgesetzt")+COUNTIFS('Controls Tracker'!$B$3:$B$95,"8.29",'Controls Tracker'!$F$3:$F$95,"Umgesetzt")+COUNTIFS('Controls Tracker'!$B$3:$B$95,"8.30",'Controls Tracker'!$F$3:$F$95,"Umgesetzt")+COUNTIFS('Controls Tracker'!$B$3:$B$95,"8.31",'Controls Tracker'!$F$3:$F$95,"Umgesetzt")+COUNTIFS('Controls Tracker'!$B$3:$B$95,"8.32",'Controls Tracker'!$F$3:$F$95,"Umgesetzt") | E15: 8 | F15: =D15/E15
B16: Art. 21(2)(f) | C16: Wirksamkeitsbewertung | D16: =COUNTIFS('Controls Tracker'!$B$3:$B$95,"5.35",'Controls Tracker'!$F$3:$F$95,"Umgesetzt")+COUNTIFS('Controls Tracker'!$B$3:$B$95,"5.36",'Controls Tracker'!$F$3:$F$95,"Umgesetzt")+COUNTIFS('Controls Tracker'!$B$3:$B$95,"8.8",'Controls Tracker'!$F$3:$F$95,"Umgesetzt") | E16: 3 | F16: =D16/E16
B17: Art. 21(2)(g) | C17: Schulung & Cyber-Hygiene | D17: =COUNTIFS('Controls Tracker'!$B$3:$B$95,"6.3",'Controls Tracker'!$F$3:$F$95,"Umgesetzt")+COUNTIFS('Controls Tracker'!$B$3:$B$95,"6.8",'Controls Tracker'!$F$3:$F$95,"Umgesetzt") | E17: 2 | F17: =D17/E17
B18: Art. 21(2)(h) | C18: Kryptographie | D18: =COUNTIFS('Controls Tracker'!$B$3:$B$95,"8.24",'Controls Tracker'!$F$3:$F$95,"Umgesetzt") | E18: 1 | F18: =D18/E18
B19: Art. 21(2)(i) | C19: HR, Zugang & Assets | D19: =COUNTIFS('Controls Tracker'!$B$3:$B$95,"5.9",'Controls Tracker'!$F$3:$F$95,"Umgesetzt")+COUNTIFS('Controls Tracker'!$B$3:$B$95,"5.10",'Controls Tracker'!$F$3:$F$95,"Umgesetzt")+COUNTIFS('Controls Tracker'!$B$3:$B$95,"5.11",'Controls Tracker'!$F$3:$F$95,"Umgesetzt")+COUNTIFS('Controls Tracker'!$B$3:$B$95,"5.15",'Controls Tracker'!$F$3:$F$95,"Umgesetzt")+COUNTIFS('Controls Tracker'!$B$3:$B$95,"5.16",'Controls Tracker'!$F$3:$F$95,"Umgesetzt")+COUNTIFS('Controls Tracker'!$B$3:$B$95,"5.17",'Controls Tracker'!$F$3:$F$95,"Umgesetzt")+COUNTIFS('Controls Tracker'!$B$3:$B$95,"5.18",'Controls Tracker'!$F$3:$F$95,"Umgesetzt")+COUNTIFS('Controls Tracker'!$B$3:$B$95,"6.1",'Controls Tracker'!$F$3:$F$95,"Umgesetzt")+COUNTIFS('Controls Tracker'!$B$3:$B$95,"6.2",'Controls Tracker'!$F$3:$F$95,"Umgesetzt")+COUNTIFS('Controls Tracker'!$B$3:$B$95,"6.5",'Controls Tracker'!$F$3:$F$95,"Umgesetzt")+COUNTIFS('Controls Tracker'!$B$3:$B$95,"8.2",'Controls Tracker'!$F$3:$F$95,"Umgesetzt")+COUNTIFS('Controls Tracker'!$B$3:$B$95,"8.5",'Controls Tracker'!$F$3:$F$95,"Umgesetzt") | E19: 12 | F19: =D19/E19
B20: Art. 21(2)(j) | C20: MFA & Kommunikation | D20: =COUNTIFS('Controls Tracker'!$B$3:$B$95,"5.14",'Controls Tracker'!$F$3:$F$95,"Umgesetzt")+COUNTIFS('Controls Tracker'!$B$3:$B$95,"8.5",'Controls Tracker'!$F$3:$F$95,"Umgesetzt")+COUNTIFS('Controls Tracker'!$B$3:$B$95,"8.20",'Controls Tracker'!$F$3:$F$95,"Umgesetzt") | E20: 3 | F20: =D20/E20

Sheet NIS2 Artikel Detail
A1: NIS2 Art. 21 — Detailansicht der Controls
A3: Art. 21(2)(a) — Risikoanalyse
A4: Control ID | B4: Control Name | C4: Kategorie | D4: Status | E4: Maßnahmen | F4: Verantwortlicher | G4: Datum
A5: 5.1 | B5: Richtlinien zur Informationssicherheit | C5: Organisatorisch | D5: ='Controls Tracker'!F3 | E5: ='Controls Tracker'!H3 | F5: ='Controls Tracker'!I3 | G5: ='Controls Tracker'!J3
A6: 5.2 | B6: Rollen und Verantwortlichkeiten | C6: Organisatorisch | D6: ='Controls Tracker'!F4 | E6: ='Controls Tracker'!H4 | F6: ='Controls Tracker'!I4 | G6: ='Controls Tracker'!J4
A7: 5.3 | B7: Aufgabentrennung | C7: Organisatorisch | D7: ='Controls Tracker'!F5 | E7: ='Controls Tracker'!H5 | F7: ='Controls Tracker'!I5 | G7: ='Controls Tracker'!J5
A8: 6.1 | B8: Überprüfung (Screening) | C8: Personell | D8: ='Controls Tracker'!F40 | E8: ='Controls Tracker'!H40 | F8: ='Controls Tracker'!I40 | G8: ='Controls Tracker'!J40
A9: 8.2 | B9: Privilegierte Zugriffsrechte | C9: Technisch | D9: ='Controls Tracker'!F63 | E9: ='Controls Tracker'!H63 | F9: ='Controls Tracker'!I63 | G9: ='Controls Tracker'!J63
A10: 8.3 | B10: Einschränkung des Informationszugriffs | C10: Technisch | D10: ='Controls Tracker'!F64 | E10: ='Controls Tracker'!H64 | F10: ='Controls Tracker'!I64 | G10: ='Controls Tracker'!J64
A12: Art. 21(2)(b) — Incident Handling
A13: Control ID | B13: Control Name | C13: Kategorie | D13: Status | E13: Maßnahmen | F13: Verantwortlicher | G13: Datum
A14: 5.24 | B14: Planung und Vorbereitung des Incident Managements | C14: Organisatorisch | D14: ='Controls Tracker'!F26 | E14: ='Controls Tracker'!H26 | F14: ='Controls Tracker'!I26 | G14: ='Controls Tracker'!J26
A15: 5.25 | B15: Beurteilung und Entscheidung bei Sicherheitsereignissen | C15: Organisatorisch | D15: ='Controls Tracker'!F27 | E15: ='Controls Tracker'!H27 | F15: ='Controls Tracker'!I27 | G15: ='Controls Tracker'!J27
A16: 5.26 | B16: Reaktion auf Sicherheitsvorfälle | C16: Organisatorisch | D16: ='Controls Tracker'!F28 | E16: ='Controls Tracker'!H28 | F16: ='Controls Tracker'!I28 | G16: ='Controls Tracker'!J28
A17: 5.27 | B17: Lernen aus Sicherheitsvorfällen | C17: Organisatorisch | D17: ='Controls Tracker'!F29 | E17: ='Controls Tracker'!H29 | F17: ='Controls Tracker'!I29 | G17: ='Controls Tracker'!J29
A18: 5.28 | B18: Beweissicherung | C18: Organisatorisch | D18: ='Controls Tracker'!F30 | E18: ='Controls Tracker'!H30 | F18: ='Controls Tracker'!I30 | G18: ='Controls Tracker'!J30
A20: Art. 21(2)(c) — BCM & Disaster Recovery
A21: Control ID | B21: Control Name | C21: Kategorie | D21: Status | E21: Maßnahmen | F21: Verantwortlicher | G21: Datum
A22: 5.29 | B22: Informationssicherheit bei Betriebsunterbrechungen | C22: Organisatorisch | D22: ='Controls Tracker'!F31 | E22: ='Controls Tracker'!H31 | F22: ='Controls Tracker'!I31 | G22: ='Controls Tracker'!J31
A23: 5.30 | B23: IKT-Bereitschaft für Business Continuity | C23: Organisatorisch | D23: ='Controls Tracker'!F32 | E23: ='Controls Tracker'!H32 | F23: ='Controls Tracker'!I32 | G23: ='Controls Tracker'!J32
A24: 8.13 | B24: Informations-Backup | C24: Technisch | D24: ='Controls Tracker'!F74 | E24: ='Controls Tracker'!H74 | F24: ='Controls Tracker'!I74 | G24: ='Controls Tracker'!J74
A25: 8.14 | B25: Redundanz von Informationsverarbeitungseinrichtungen | C25: Technisch | D25: ='Controls Tracker'!F75 | E25: ='Controls Tracker'!H75 | F25: ='Controls Tracker'!I75 | G25: ='Controls Tracker'!J75
A27: Art. 21(2)(d) — Lieferkettensicherheit
A28: Control ID | B28: Control Name | C28: Kategorie | D28: Status | E28: Maßnahmen | F28: Verantwortlicher | G28: Datum
A29: 5.19 | B29: Informationssicherheit in Lieferantenbeziehungen | C29: Organisatorisch | D29: ='Controls Tracker'!F21 | E29: ='Controls Tracker'!H21 | F29: ='Controls Tracker'!I21 | G29: ='Controls Tracker'!J21
A30: 5.20 | B30: Informationssicherheit in Lieferantenvereinbarungen | C30: Organisatorisch | D30: ='Controls Tracker'!F22 | E30: ='Controls Tracker'!H22 | F30: ='Controls Tracker'!I22 | G30: ='Controls Tracker'!J22
A31: 5.21 | B31: Informationssicherheit in der IKT-Lieferkette | C31: Organisatorisch | D31: ='Controls Tracker'!F23 | E31: ='Controls Tracker'!H23 | F31: ='Controls Tracker'!I23 | G31: ='Controls Tracker'!J23
A32: 5.22 | B32: Überwachung und Management von Lieferantendiensten | C32: Organisatorisch | D32: ='Controls Tracker'!F24 | E32: ='Controls Tracker'!H24 | F32: ='Controls Tracker'!I24 | G32: ='Controls Tracker'!J24
A33: 5.23 | B33: Informationssicherheit bei Cloud-Diensten | C33: Organisatorisch | D33: ='Controls Tracker'!F25 | E33: ='Controls Tracker'!H25 | F33: ='Controls Tracker'!I25 | G33: ='Controls Tracker'!J25
A35: Art. 21(2)(e) — Sichere Entwicklung
A36: Control ID | B36: Control Name | C36: Kategorie | D36: Status | E36: Maßnahmen | F36: Verantwortlicher | G36: Datum
A37: 8.25 | B37: Sicherer Entwicklungslebenszyklus | C37: Technisch | D37: ='Controls Tracker'!F86 | E37: ='Controls Tracker'!H86 | F37: ='Controls Tracker'!I86 | G37: ='Controls Tracker'!J86
A38: 8.26 | B38: Anforderungen an die Anwendungssicherheit | C38: Technisch | D38: ='Controls Tracker'!F87 | E38: ='Controls Tracker'!H87 | F38: ='Controls Tracker'!I87 | G38: ='Controls Tracker'!J87
A39: 8.27 | B39: Sichere System-Architektur und Ingenieursprinzipien | C39: Technisch | D39: ='Controls Tracker'!F88 | E39: ='Controls Tracker'!H88 | F39: ='Controls Tracker'!I88 | G39: ='Controls Tracker'!J88
A40: 8.28 | B40: Sicheres Codieren | C40: Technisch | D40: ='Controls Tracker'!F89 | E40: ='Controls Tracker'!H89 | F40: ='Controls Tracker'!I89 | G40: ='Controls Tracker'!J89
A41: 8.29 | B41: Sicherheitstests in Entwicklung und Abnahme | C41: Technisch | D41: ='Controls Tracker'!F90 | E41: ='Controls Tracker'!H90 | F41: ='Controls Tracker'!I90 | G41: ='Controls Tracker'!J90
A42: 8.30 | B42: Ausgelagerte Entwicklung | C42: Technisch | D42: ='Controls Tracker'!F91 | E42: ='Controls Tracker'!H91 | F42: ='Controls Tracker'!I91 | G42: ='Controls Tracker'!J91
A43: 8.31 | B43: Trennung von Entwicklungs-, Test- und Produktionsumgebungen | C43: Technisch | D43: ='Controls Tracker'!F92 | E43: ='Controls Tracker'!H92 | F43: ='Controls Tracker'!I92 | G43: ='Controls Tracker'!J92
A44: 8.32 | B44: Änderungsmanagement | C44: Technisch | D44: ='Controls Tracker'!F93 | E44: ='Controls Tracker'!H93 | F44: ='Controls Tracker'!I93 | G44: ='Controls Tracker'!J93
A46: Art. 21(2)(f) — Wirksamkeitsbewertung
...
